-------------------------------------------------------------------------------
Test set: TestSuite
-------------------------------------------------------------------------------
Tests run: 5, Failures: 1, Errors: 0, Skipped: 0, Time elapsed: 28.222 s <<< FAILURE! - in TestSuite
rahulshettyacademy.tests.ErrorValidationsTest.ProductErrorValidation  Time elapsed: 2.677 s  <<< FAILURE!
java.lang.AssertionError: expected [false] but found [true]
	at org.testng.Assert.fail(Assert.java:96)
	at org.testng.Assert.failNotEquals(Assert.java:776)
	at org.testng.Assert.assertFalse(Assert.java:65)
	at org.testng.Assert.assertFalse(Assert.java:75)
	at rahulshettyacademy.tests.ErrorValidationsTest.ProductErrorValidation(ErrorValidationsTest.java:41)
	at java.base/jdk.internal.reflect.DirectMethodHandleAccessor.invoke(DirectMethodHandleAccessor.java:103)
	at java.base/java.lang.reflect.Method.invoke(Method.java:580)
	at org.testng.internal.MethodInvocationHelper.invokeMethod(MethodInvocationHelper.java:124)
	at org.testng.internal.Invoker.invokeMethod(Invoker.java:583)
	at org.testng.internal.Invoker.invokeTestMethod(Invoker.java:719)
	at org.testng.internal.Invoker.invokeTestMethods(Invoker.java:989)
	at org.testng.internal.TestMethodWorker.invokeTestMethods(TestMethodWorker.java:125)
	at org.testng.internal.TestMethodWorker.run(TestMethodWorker.java:109)
	at org.testng.TestRunner.privateRun(TestRunner.java:648)
	at org.testng.TestRunner.run(TestRunner.java:505)
	at org.testng.SuiteRunner.runTest(SuiteRunner.java:455)
	at org.testng.SuiteRunner.access$000(SuiteRunner.java:40)
	at org.testng.SuiteRunner$SuiteWorker.run(SuiteRunner.java:489)
	at org.testng.internal.thread.ThreadUtil$1.call(ThreadUtil.java:52)
	at java.base/java.util.concurrent.FutureTask.run(FutureTask.java:317)
	at java.base/java.util.concurrent.ThreadPoolExecutor.runWorker(ThreadPoolExecutor.java:1144)
	at java.base/java.util.concurrent.ThreadPoolExecutor$Worker.run(ThreadPoolExecutor.java:642)
	at java.base/java.lang.Thread.run(Thread.java:1583)

